werkzeug - INFO - [31m[1mWARNING: This is a development server. Do not use it in a production deployment. Use a production WSGI server instead.[0m
 * Running on http://127.0.0.1:5000
werkzeug - INFO - [33mPress CTRL+C to quit[0m
werkzeug - INFO - [31m[1mWARNING: This is a development server. Do not use it in a production deployment. Use a production WSGI server instead.[0m
 * Running on http://127.0.0.1:5000
werkzeug - INFO - [33mPress CTRL+C to quit[0m
root - INFO - Chores retrieved successfully
flask-server - ERROR - Exception on /api/get-chores [GET]
Traceback (most recent call last):
  File "/Users/davidekim/tensorflow/lib/python3.9/site-packages/flask/app.py", line 2529, in wsgi_app
    response = self.full_dispatch_request()
  File "/Users/davidekim/tensorflow/lib/python3.9/site-packages/flask/app.py", line 1825, in full_dispatch_request
    rv = self.handle_user_exception(e)
  File "/Users/davidekim/tensorflow/lib/python3.9/site-packages/flask_cors/extension.py", line 176, in wrapped_function
    return cors_after_request(app.make_response(f(*args, **kwargs)))
  File "/Users/davidekim/tensorflow/lib/python3.9/site-packages/flask/app.py", line 1823, in full_dispatch_request
    rv = self.dispatch_request()
  File "/Users/davidekim/tensorflow/lib/python3.9/site-packages/flask/app.py", line 1799, in dispatch_request
    return self.ensure_sync(self.view_functions[rule.endpoint])(**view_args)
  File "/Users/davidekim/Desktop/DataScience/Hackathon2/team561/flask-server.py", line 120, in get_chores
    return jsonify([dict(row) for row in chores]), 200
  File "/Users/davidekim/Desktop/DataScience/Hackathon2/team561/flask-server.py", line 120, in <listcomp>
    return jsonify([dict(row) for row in chores]), 200
ValueError: dictionary update sequence element #0 has length 12; 2 is required
werkzeug - INFO - 127.0.0.1 - - [18/Nov/2023 21:56:10] "[35m[1mGET /api/get-chores HTTP/1.1[0m" 500 -
root - INFO - Allowance retrieved successfully
flask-server - ERROR - Exception on /api/get-allowance [GET]
Traceback (most recent call last):
  File "/Users/davidekim/tensorflow/lib/python3.9/site-packages/flask/app.py", line 2529, in wsgi_app
    response = self.full_dispatch_request()
  File "/Users/davidekim/tensorflow/lib/python3.9/site-packages/flask/app.py", line 1825, in full_dispatch_request
    rv = self.handle_user_exception(e)
  File "/Users/davidekim/tensorflow/lib/python3.9/site-packages/flask_cors/extension.py", line 176, in wrapped_function
    return cors_after_request(app.make_response(f(*args, **kwargs)))
  File "/Users/davidekim/tensorflow/lib/python3.9/site-packages/flask/app.py", line 1823, in full_dispatch_request
    rv = self.dispatch_request()
  File "/Users/davidekim/tensorflow/lib/python3.9/site-packages/flask/app.py", line 1799, in dispatch_request
    return self.ensure_sync(self.view_functions[rule.endpoint])(**view_args)
  File "/Users/davidekim/Desktop/DataScience/Hackathon2/team561/flask-server.py", line 97, in get_allowance
    return jsonify({'allowance': result['amount'] if result else 0}), 200
  File "lib/sqlalchemy/cyextension/resultproxy.pyx", line 48, in sqlalchemy.cyextension.resultproxy.BaseRow.__getitem__
TypeError: tuple indices must be integers or slices, not str
werkzeug - INFO - 127.0.0.1 - - [18/Nov/2023 21:56:10] "[35m[1mGET /api/get-allowance HTTP/1.1[0m" 500 -
root - INFO - Allowance retrieved successfully
flask-server - ERROR - Exception on /api/get-allowance [GET]
Traceback (most recent call last):
  File "/Users/davidekim/tensorflow/lib/python3.9/site-packages/flask/app.py", line 2529, in wsgi_app
    response = self.full_dispatch_request()
  File "/Users/davidekim/tensorflow/lib/python3.9/site-packages/flask/app.py", line 1825, in full_dispatch_request
    rv = self.handle_user_exception(e)
  File "/Users/davidekim/tensorflow/lib/python3.9/site-packages/flask_cors/extension.py", line 176, in wrapped_function
    return cors_after_request(app.make_response(f(*args, **kwargs)))
  File "/Users/davidekim/tensorflow/lib/python3.9/site-packages/flask/app.py", line 1823, in full_dispatch_request
    rv = self.dispatch_request()
  File "/Users/davidekim/tensorflow/lib/python3.9/site-packages/flask/app.py", line 1799, in dispatch_request
    return self.ensure_sync(self.view_functions[rule.endpoint])(**view_args)
  File "/Users/davidekim/Desktop/DataScience/Hackathon2/team561/flask-server.py", line 97, in get_allowance
    return jsonify({'allowance': result['amount'] if result else 0}), 200
  File "lib/sqlalchemy/cyextension/resultproxy.pyx", line 48, in sqlalchemy.cyextension.resultproxy.BaseRow.__getitem__
TypeError: tuple indices must be integers or slices, not str
werkzeug - INFO - 127.0.0.1 - - [18/Nov/2023 21:56:10] "[35m[1mGET /api/get-allowance HTTP/1.1[0m" 500 -
root - INFO - Chores retrieved successfully
flask-server - ERROR - Exception on /api/get-chores [GET]
Traceback (most recent call last):
  File "/Users/davidekim/tensorflow/lib/python3.9/site-packages/flask/app.py", line 2529, in wsgi_app
    response = self.full_dispatch_request()
  File "/Users/davidekim/tensorflow/lib/python3.9/site-packages/flask/app.py", line 1825, in full_dispatch_request
    rv = self.handle_user_exception(e)
  File "/Users/davidekim/tensorflow/lib/python3.9/site-packages/flask_cors/extension.py", line 176, in wrapped_function
    return cors_after_request(app.make_response(f(*args, **kwargs)))
  File "/Users/davidekim/tensorflow/lib/python3.9/site-packages/flask/app.py", line 1823, in full_dispatch_request
    rv = self.dispatch_request()
  File "/Users/davidekim/tensorflow/lib/python3.9/site-packages/flask/app.py", line 1799, in dispatch_request
    return self.ensure_sync(self.view_functions[rule.endpoint])(**view_args)
  File "/Users/davidekim/Desktop/DataScience/Hackathon2/team561/flask-server.py", line 120, in get_chores
    return jsonify([dict(row) for row in chores]), 200
  File "/Users/davidekim/Desktop/DataScience/Hackathon2/team561/flask-server.py", line 120, in <listcomp>
    return jsonify([dict(row) for row in chores]), 200
ValueError: dictionary update sequence element #0 has length 12; 2 is required
werkzeug - INFO - 127.0.0.1 - - [18/Nov/2023 21:56:10] "[35m[1mGET /api/get-chores HTTP/1.1[0m" 500 -
root - INFO - Chores retrieved successfully
flask-server - ERROR - Exception on /api/get-chores [GET]
Traceback (most recent call last):
  File "/Users/davidekim/tensorflow/lib/python3.9/site-packages/flask/app.py", line 2529, in wsgi_app
    response = self.full_dispatch_request()
  File "/Users/davidekim/tensorflow/lib/python3.9/site-packages/flask/app.py", line 1825, in full_dispatch_request
    rv = self.handle_user_exception(e)
  File "/Users/davidekim/tensorflow/lib/python3.9/site-packages/flask_cors/extension.py", line 176, in wrapped_function
    return cors_after_request(app.make_response(f(*args, **kwargs)))
  File "/Users/davidekim/tensorflow/lib/python3.9/site-packages/flask/app.py", line 1823, in full_dispatch_request
    rv = self.dispatch_request()
  File "/Users/davidekim/tensorflow/lib/python3.9/site-packages/flask/app.py", line 1799, in dispatch_request
    return self.ensure_sync(self.view_functions[rule.endpoint])(**view_args)
  File "/Users/davidekim/Desktop/DataScience/Hackathon2/team561/flask-server.py", line 120, in get_chores
    return jsonify([dict(row) for row in chores]), 200
  File "/Users/davidekim/Desktop/DataScience/Hackathon2/team561/flask-server.py", line 120, in <listcomp>
    return jsonify([dict(row) for row in chores]), 200
ValueError: dictionary update sequence element #0 has length 12; 2 is required
werkzeug - INFO - 127.0.0.1 - - [18/Nov/2023 21:56:13] "[35m[1mGET /api/get-chores HTTP/1.1[0m" 500 -
root - INFO - Item retrieved successfully
flask-server - ERROR - Exception on /api/get-item [GET]
Traceback (most recent call last):
  File "/Users/davidekim/tensorflow/lib/python3.9/site-packages/flask/app.py", line 2529, in wsgi_app
    response = self.full_dispatch_request()
  File "/Users/davidekim/tensorflow/lib/python3.9/site-packages/flask/app.py", line 1825, in full_dispatch_request
    rv = self.handle_user_exception(e)
  File "/Users/davidekim/tensorflow/lib/python3.9/site-packages/flask_cors/extension.py", line 176, in wrapped_function
    return cors_after_request(app.make_response(f(*args, **kwargs)))
  File "/Users/davidekim/tensorflow/lib/python3.9/site-packages/flask/app.py", line 1823, in full_dispatch_request
    rv = self.dispatch_request()
  File "/Users/davidekim/tensorflow/lib/python3.9/site-packages/flask/app.py", line 1799, in dispatch_request
    return self.ensure_sync(self.view_functions[rule.endpoint])(**view_args)
  File "/Users/davidekim/Desktop/DataScience/Hackathon2/team561/flask-server.py", line 71, in get_item
    return jsonify(dict(result)) if result else jsonify({'error': 'No item found'}), 404 if not result else 200
ValueError: dictionary update sequence element #0 has length 7; 2 is required
werkzeug - INFO - 127.0.0.1 - - [18/Nov/2023 21:56:13] "[35m[1mGET /api/get-item HTTP/1.1[0m" 500 -
root - INFO - Total balance calculated successfully
werkzeug - INFO - 127.0.0.1 - - [18/Nov/2023 21:56:13] "GET /api/get-total-balance HTTP/1.1" 200 -
root - INFO - Chores retrieved successfully
root - INFO - Item retrieved successfully
flask-server - ERROR - Exception on /api/get-chores [GET]
Traceback (most recent call last):
  File "/Users/davidekim/tensorflow/lib/python3.9/site-packages/flask/app.py", line 2529, in wsgi_app
    response = self.full_dispatch_request()
  File "/Users/davidekim/tensorflow/lib/python3.9/site-packages/flask/app.py", line 1825, in full_dispatch_request
    rv = self.handle_user_exception(e)
  File "/Users/davidekim/tensorflow/lib/python3.9/site-packages/flask_cors/extension.py", line 176, in wrapped_function
    return cors_after_request(app.make_response(f(*args, **kwargs)))
  File "/Users/davidekim/tensorflow/lib/python3.9/site-packages/flask/app.py", line 1823, in full_dispatch_request
    rv = self.dispatch_request()
  File "/Users/davidekim/tensorflow/lib/python3.9/site-packages/flask/app.py", line 1799, in dispatch_request
    return self.ensure_sync(self.view_functions[rule.endpoint])(**view_args)
  File "/Users/davidekim/Desktop/DataScience/Hackathon2/team561/flask-server.py", line 120, in get_chores
    return jsonify([dict(row) for row in chores]), 200
  File "/Users/davidekim/Desktop/DataScience/Hackathon2/team561/flask-server.py", line 120, in <listcomp>
    return jsonify([dict(row) for row in chores]), 200
ValueError: dictionary update sequence element #0 has length 12; 2 is required
flask-server - ERROR - Exception on /api/get-item [GET]
Traceback (most recent call last):
  File "/Users/davidekim/tensorflow/lib/python3.9/site-packages/flask/app.py", line 2529, in wsgi_app
    response = self.full_dispatch_request()
  File "/Users/davidekim/tensorflow/lib/python3.9/site-packages/flask/app.py", line 1825, in full_dispatch_request
    rv = self.handle_user_exception(e)
  File "/Users/davidekim/tensorflow/lib/python3.9/site-packages/flask_cors/extension.py", line 176, in wrapped_function
    return cors_after_request(app.make_response(f(*args, **kwargs)))
  File "/Users/davidekim/tensorflow/lib/python3.9/site-packages/flask/app.py", line 1823, in full_dispatch_request
    rv = self.dispatch_request()
  File "/Users/davidekim/tensorflow/lib/python3.9/site-packages/flask/app.py", line 1799, in dispatch_request
    return self.ensure_sync(self.view_functions[rule.endpoint])(**view_args)
  File "/Users/davidekim/Desktop/DataScience/Hackathon2/team561/flask-server.py", line 71, in get_item
    return jsonify(dict(result)) if result else jsonify({'error': 'No item found'}), 404 if not result else 200
ValueError: dictionary update sequence element #0 has length 7; 2 is required
werkzeug - INFO - 127.0.0.1 - - [18/Nov/2023 22:00:28] "[35m[1mGET /api/get-chores HTTP/1.1[0m" 500 -
werkzeug - INFO - 127.0.0.1 - - [18/Nov/2023 22:00:28] "[35m[1mGET /api/get-item HTTP/1.1[0m" 500 -
root - INFO - Total balance calculated successfully
werkzeug - INFO - 127.0.0.1 - - [18/Nov/2023 22:00:28] "GET /api/get-total-balance HTTP/1.1" 200 -
root - INFO - Item retrieved successfully
flask-server - ERROR - Exception on /api/get-item [GET]
Traceback (most recent call last):
  File "/Users/davidekim/tensorflow/lib/python3.9/site-packages/flask/app.py", line 2529, in wsgi_app
    response = self.full_dispatch_request()
  File "/Users/davidekim/tensorflow/lib/python3.9/site-packages/flask/app.py", line 1825, in full_dispatch_request
    rv = self.handle_user_exception(e)
  File "/Users/davidekim/tensorflow/lib/python3.9/site-packages/flask_cors/extension.py", line 176, in wrapped_function
    return cors_after_request(app.make_response(f(*args, **kwargs)))
  File "/Users/davidekim/tensorflow/lib/python3.9/site-packages/flask/app.py", line 1823, in full_dispatch_request
    rv = self.dispatch_request()
  File "/Users/davidekim/tensorflow/lib/python3.9/site-packages/flask/app.py", line 1799, in dispatch_request
    return self.ensure_sync(self.view_functions[rule.endpoint])(**view_args)
  File "/Users/davidekim/Desktop/DataScience/Hackathon2/team561/flask-server.py", line 71, in get_item
    return jsonify(dict(result)) if result else jsonify({'error': 'No item found'}), 404 if not result else 200
ValueError: dictionary update sequence element #0 has length 7; 2 is required
werkzeug - INFO - 127.0.0.1 - - [18/Nov/2023 22:00:33] "[35m[1mGET /api/get-item HTTP/1.1[0m" 500 -
root - INFO - Chores retrieved successfully
flask-server - ERROR - Exception on /api/get-chores [GET]
Traceback (most recent call last):
  File "/Users/davidekim/tensorflow/lib/python3.9/site-packages/flask/app.py", line 2529, in wsgi_app
    response = self.full_dispatch_request()
  File "/Users/davidekim/tensorflow/lib/python3.9/site-packages/flask/app.py", line 1825, in full_dispatch_request
    rv = self.handle_user_exception(e)
  File "/Users/davidekim/tensorflow/lib/python3.9/site-packages/flask_cors/extension.py", line 176, in wrapped_function
    return cors_after_request(app.make_response(f(*args, **kwargs)))
  File "/Users/davidekim/tensorflow/lib/python3.9/site-packages/flask/app.py", line 1823, in full_dispatch_request
    rv = self.dispatch_request()
  File "/Users/davidekim/tensorflow/lib/python3.9/site-packages/flask/app.py", line 1799, in dispatch_request
    return self.ensure_sync(self.view_functions[rule.endpoint])(**view_args)
  File "/Users/davidekim/Desktop/DataScience/Hackathon2/team561/flask-server.py", line 120, in get_chores
    return jsonify([dict(row) for row in chores]), 200
  File "/Users/davidekim/Desktop/DataScience/Hackathon2/team561/flask-server.py", line 120, in <listcomp>
    return jsonify([dict(row) for row in chores]), 200
ValueError: dictionary update sequence element #0 has length 12; 2 is required
werkzeug - INFO - 127.0.0.1 - - [18/Nov/2023 22:00:33] "[35m[1mGET /api/get-chores HTTP/1.1[0m" 500 -
root - INFO - Total balance calculated successfully
werkzeug - INFO - 127.0.0.1 - - [18/Nov/2023 22:00:33] "GET /api/get-total-balance HTTP/1.1" 200 -
root - INFO - Item retrieved successfully
flask-server - ERROR - Exception on /api/get-item [GET]
Traceback (most recent call last):
  File "/Users/davidekim/tensorflow/lib/python3.9/site-packages/flask/app.py", line 2529, in wsgi_app
    response = self.full_dispatch_request()
  File "/Users/davidekim/tensorflow/lib/python3.9/site-packages/flask/app.py", line 1825, in full_dispatch_request
    rv = self.handle_user_exception(e)
  File "/Users/davidekim/tensorflow/lib/python3.9/site-packages/flask_cors/extension.py", line 176, in wrapped_function
    return cors_after_request(app.make_response(f(*args, **kwargs)))
  File "/Users/davidekim/tensorflow/lib/python3.9/site-packages/flask/app.py", line 1823, in full_dispatch_request
    rv = self.dispatch_request()
  File "/Users/davidekim/tensorflow/lib/python3.9/site-packages/flask/app.py", line 1799, in dispatch_request
    return self.ensure_sync(self.view_functions[rule.endpoint])(**view_args)
  File "/Users/davidekim/Desktop/DataScience/Hackathon2/team561/flask-server.py", line 71, in get_item
    return jsonify(dict(result)) if result else jsonify({'error': 'No item found'}), 404 if not result else 200
ValueError: dictionary update sequence element #0 has length 7; 2 is required
werkzeug - INFO - 127.0.0.1 - - [18/Nov/2023 22:01:23] "[35m[1mGET /api/get-item HTTP/1.1[0m" 500 -
root - INFO - Chores retrieved successfully
flask-server - ERROR - Exception on /api/get-chores [GET]
Traceback (most recent call last):
  File "/Users/davidekim/tensorflow/lib/python3.9/site-packages/flask/app.py", line 2529, in wsgi_app
    response = self.full_dispatch_request()
  File "/Users/davidekim/tensorflow/lib/python3.9/site-packages/flask/app.py", line 1825, in full_dispatch_request
    rv = self.handle_user_exception(e)
  File "/Users/davidekim/tensorflow/lib/python3.9/site-packages/flask_cors/extension.py", line 176, in wrapped_function
    return cors_after_request(app.make_response(f(*args, **kwargs)))
  File "/Users/davidekim/tensorflow/lib/python3.9/site-packages/flask/app.py", line 1823, in full_dispatch_request
    rv = self.dispatch_request()
  File "/Users/davidekim/tensorflow/lib/python3.9/site-packages/flask/app.py", line 1799, in dispatch_request
    return self.ensure_sync(self.view_functions[rule.endpoint])(**view_args)
  File "/Users/davidekim/Desktop/DataScience/Hackathon2/team561/flask-server.py", line 120, in get_chores
    return jsonify([dict(row) for row in chores]), 200
  File "/Users/davidekim/Desktop/DataScience/Hackathon2/team561/flask-server.py", line 120, in <listcomp>
    return jsonify([dict(row) for row in chores]), 200
ValueError: dictionary update sequence element #0 has length 12; 2 is required
werkzeug - INFO - 127.0.0.1 - - [18/Nov/2023 22:01:23] "[35m[1mGET /api/get-chores HTTP/1.1[0m" 500 -
root - INFO - Total balance calculated successfully
werkzeug - INFO - 127.0.0.1 - - [18/Nov/2023 22:01:23] "GET /api/get-total-balance HTTP/1.1" 200 -
root - INFO - Item retrieved successfully
root - INFO - Chores retrieved successfully
flask-server - ERROR - Exception on /api/get-item [GET]
Traceback (most recent call last):
  File "/Users/davidekim/tensorflow/lib/python3.9/site-packages/flask/app.py", line 2529, in wsgi_app
    response = self.full_dispatch_request()
  File "/Users/davidekim/tensorflow/lib/python3.9/site-packages/flask/app.py", line 1825, in full_dispatch_request
    rv = self.handle_user_exception(e)
  File "/Users/davidekim/tensorflow/lib/python3.9/site-packages/flask_cors/extension.py", line 176, in wrapped_function
    return cors_after_request(app.make_response(f(*args, **kwargs)))
  File "/Users/davidekim/tensorflow/lib/python3.9/site-packages/flask/app.py", line 1823, in full_dispatch_request
    rv = self.dispatch_request()
  File "/Users/davidekim/tensorflow/lib/python3.9/site-packages/flask/app.py", line 1799, in dispatch_request
    return self.ensure_sync(self.view_functions[rule.endpoint])(**view_args)
  File "/Users/davidekim/Desktop/DataScience/Hackathon2/team561/flask-server.py", line 71, in get_item
    return jsonify(dict(result)) if result else jsonify({'error': 'No item found'}), 404 if not result else 200
ValueError: dictionary update sequence element #0 has length 7; 2 is required
flask-server - ERROR - Exception on /api/get-chores [GET]
Traceback (most recent call last):
  File "/Users/davidekim/tensorflow/lib/python3.9/site-packages/flask/app.py", line 2529, in wsgi_app
    response = self.full_dispatch_request()
  File "/Users/davidekim/tensorflow/lib/python3.9/site-packages/flask/app.py", line 1825, in full_dispatch_request
    rv = self.handle_user_exception(e)
  File "/Users/davidekim/tensorflow/lib/python3.9/site-packages/flask_cors/extension.py", line 176, in wrapped_function
    return cors_after_request(app.make_response(f(*args, **kwargs)))
  File "/Users/davidekim/tensorflow/lib/python3.9/site-packages/flask/app.py", line 1823, in full_dispatch_request
    rv = self.dispatch_request()
  File "/Users/davidekim/tensorflow/lib/python3.9/site-packages/flask/app.py", line 1799, in dispatch_request
    return self.ensure_sync(self.view_functions[rule.endpoint])(**view_args)
  File "/Users/davidekim/Desktop/DataScience/Hackathon2/team561/flask-server.py", line 120, in get_chores
    return jsonify([dict(row) for row in chores]), 200
  File "/Users/davidekim/Desktop/DataScience/Hackathon2/team561/flask-server.py", line 120, in <listcomp>
    return jsonify([dict(row) for row in chores]), 200
ValueError: dictionary update sequence element #0 has length 12; 2 is required
werkzeug - INFO - 127.0.0.1 - - [18/Nov/2023 22:01:41] "[35m[1mGET /api/get-item HTTP/1.1[0m" 500 -
werkzeug - INFO - 127.0.0.1 - - [18/Nov/2023 22:01:41] "[35m[1mGET /api/get-chores HTTP/1.1[0m" 500 -
root - INFO - Total balance calculated successfully
werkzeug - INFO - 127.0.0.1 - - [18/Nov/2023 22:01:41] "GET /api/get-total-balance HTTP/1.1" 200 -
root - INFO - Chores retrieved successfully
root - INFO - Allowance retrieved successfully
flask-server - ERROR - Exception on /api/get-chores [GET]
Traceback (most recent call last):
  File "/Users/davidekim/tensorflow/lib/python3.9/site-packages/flask/app.py", line 2529, in wsgi_app
    response = self.full_dispatch_request()
  File "/Users/davidekim/tensorflow/lib/python3.9/site-packages/flask/app.py", line 1825, in full_dispatch_request
    rv = self.handle_user_exception(e)
  File "/Users/davidekim/tensorflow/lib/python3.9/site-packages/flask_cors/extension.py", line 176, in wrapped_function
    return cors_after_request(app.make_response(f(*args, **kwargs)))
  File "/Users/davidekim/tensorflow/lib/python3.9/site-packages/flask/app.py", line 1823, in full_dispatch_request
    rv = self.dispatch_request()
  File "/Users/davidekim/tensorflow/lib/python3.9/site-packages/flask/app.py", line 1799, in dispatch_request
    return self.ensure_sync(self.view_functions[rule.endpoint])(**view_args)
  File "/Users/davidekim/Desktop/DataScience/Hackathon2/team561/flask-server.py", line 120, in get_chores
    return jsonify([dict(row) for row in chores]), 200
  File "/Users/davidekim/Desktop/DataScience/Hackathon2/team561/flask-server.py", line 120, in <listcomp>
    return jsonify([dict(row) for row in chores]), 200
ValueError: dictionary update sequence element #0 has length 12; 2 is required
flask-server - ERROR - Exception on /api/get-allowance [GET]
Traceback (most recent call last):
  File "/Users/davidekim/tensorflow/lib/python3.9/site-packages/flask/app.py", line 2529, in wsgi_app
    response = self.full_dispatch_request()
  File "/Users/davidekim/tensorflow/lib/python3.9/site-packages/flask/app.py", line 1825, in full_dispatch_request
    rv = self.handle_user_exception(e)
  File "/Users/davidekim/tensorflow/lib/python3.9/site-packages/flask_cors/extension.py", line 176, in wrapped_function
    return cors_after_request(app.make_response(f(*args, **kwargs)))
  File "/Users/davidekim/tensorflow/lib/python3.9/site-packages/flask/app.py", line 1823, in full_dispatch_request
    rv = self.dispatch_request()
  File "/Users/davidekim/tensorflow/lib/python3.9/site-packages/flask/app.py", line 1799, in dispatch_request
    return self.ensure_sync(self.view_functions[rule.endpoint])(**view_args)
  File "/Users/davidekim/Desktop/DataScience/Hackathon2/team561/flask-server.py", line 97, in get_allowance
    return jsonify({'allowance': result['amount'] if result else 0}), 200
  File "lib/sqlalchemy/cyextension/resultproxy.pyx", line 48, in sqlalchemy.cyextension.resultproxy.BaseRow.__getitem__
TypeError: tuple indices must be integers or slices, not str
werkzeug - INFO - 127.0.0.1 - - [18/Nov/2023 22:05:50] "[35m[1mGET /api/get-chores HTTP/1.1[0m" 500 -
werkzeug - INFO - 127.0.0.1 - - [18/Nov/2023 22:05:50] "[35m[1mGET /api/get-allowance HTTP/1.1[0m" 500 -
root - INFO - Inserting allowance: {'amount': 765789}
flask-server - ERROR - Exception on /api/insert-allowance [POST]
Traceback (most recent call last):
  File "/Users/davidekim/tensorflow/lib/python3.9/site-packages/flask/app.py", line 2529, in wsgi_app
    response = self.full_dispatch_request()
  File "/Users/davidekim/tensorflow/lib/python3.9/site-packages/flask/app.py", line 1825, in full_dispatch_request
    rv = self.handle_user_exception(e)
  File "/Users/davidekim/tensorflow/lib/python3.9/site-packages/flask_cors/extension.py", line 176, in wrapped_function
    return cors_after_request(app.make_response(f(*args, **kwargs)))
  File "/Users/davidekim/tensorflow/lib/python3.9/site-packages/flask/app.py", line 1823, in full_dispatch_request
    rv = self.dispatch_request()
  File "/Users/davidekim/tensorflow/lib/python3.9/site-packages/flask/app.py", line 1799, in dispatch_request
    return self.ensure_sync(self.view_functions[rule.endpoint])(**view_args)
  File "/Users/davidekim/Desktop/DataScience/Hackathon2/team561/flask-server.py", line 84, in insert_allowance
    return response if 'error' in response else jsonify({'message': 'Allowance added successfully'}), 201 if 'error' not in response else 500
TypeError: argument of type 'NoneType' is not iterable
werkzeug - INFO - 127.0.0.1 - - [18/Nov/2023 22:05:53] "[35m[1mPOST /api/insert-allowance HTTP/1.1[0m" 500 -
root - INFO - Inserting chore: {'name': 'New Chore', 'compensation': 0}
flask-server - ERROR - Exception on /api/insert-chore [POST]
Traceback (most recent call last):
  File "/Users/davidekim/tensorflow/lib/python3.9/site-packages/flask/app.py", line 2529, in wsgi_app
    response = self.full_dispatch_request()
  File "/Users/davidekim/tensorflow/lib/python3.9/site-packages/flask/app.py", line 1825, in full_dispatch_request
    rv = self.handle_user_exception(e)
  File "/Users/davidekim/tensorflow/lib/python3.9/site-packages/flask_cors/extension.py", line 176, in wrapped_function
    return cors_after_request(app.make_response(f(*args, **kwargs)))
  File "/Users/davidekim/tensorflow/lib/python3.9/site-packages/flask/app.py", line 1823, in full_dispatch_request
    rv = self.dispatch_request()
  File "/Users/davidekim/tensorflow/lib/python3.9/site-packages/flask/app.py", line 1799, in dispatch_request
    return self.ensure_sync(self.view_functions[rule.endpoint])(**view_args)
  File "/Users/davidekim/Desktop/DataScience/Hackathon2/team561/flask-server.py", line 110, in insert_chore
    return response if 'error' in response else jsonify({'message': 'Chore added successfully'}), 201 if 'error' not in response else 500
TypeError: argument of type 'NoneType' is not iterable
werkzeug - INFO - 127.0.0.1 - - [18/Nov/2023 22:05:54] "[35m[1mPOST /api/insert-chore HTTP/1.1[0m" 500 -
root - INFO - Inserting chore: {'name': 'New Chore', 'compensation': 0}
root - INFO - Inserting chore: {'name': 'New Chore', 'compensation': 0}
flask-server - ERROR - Exception on /api/insert-chore [POST]
Traceback (most recent call last):
  File "/Users/davidekim/tensorflow/lib/python3.9/site-packages/flask/app.py", line 2529, in wsgi_app
    response = self.full_dispatch_request()
  File "/Users/davidekim/tensorflow/lib/python3.9/site-packages/flask/app.py", line 1825, in full_dispatch_request
    rv = self.handle_user_exception(e)
  File "/Users/davidekim/tensorflow/lib/python3.9/site-packages/flask_cors/extension.py", line 176, in wrapped_function
    return cors_after_request(app.make_response(f(*args, **kwargs)))
  File "/Users/davidekim/tensorflow/lib/python3.9/site-packages/flask/app.py", line 1823, in full_dispatch_request
    rv = self.dispatch_request()
  File "/Users/davidekim/tensorflow/lib/python3.9/site-packages/flask/app.py", line 1799, in dispatch_request
    return self.ensure_sync(self.view_functions[rule.endpoint])(**view_args)
  File "/Users/davidekim/Desktop/DataScience/Hackathon2/team561/flask-server.py", line 110, in insert_chore
    return response if 'error' in response else jsonify({'message': 'Chore added successfully'}), 201 if 'error' not in response else 500
TypeError: argument of type 'NoneType' is not iterable
werkzeug - INFO - 127.0.0.1 - - [18/Nov/2023 22:05:55] "[35m[1mPOST /api/insert-chore HTTP/1.1[0m" 500 -
flask-server - ERROR - Exception on /api/insert-chore [POST]
Traceback (most recent call last):
  File "/Users/davidekim/tensorflow/lib/python3.9/site-packages/flask/app.py", line 2529, in wsgi_app
    response = self.full_dispatch_request()
  File "/Users/davidekim/tensorflow/lib/python3.9/site-packages/flask/app.py", line 1825, in full_dispatch_request
    rv = self.handle_user_exception(e)
  File "/Users/davidekim/tensorflow/lib/python3.9/site-packages/flask_cors/extension.py", line 176, in wrapped_function
    return cors_after_request(app.make_response(f(*args, **kwargs)))
  File "/Users/davidekim/tensorflow/lib/python3.9/site-packages/flask/app.py", line 1823, in full_dispatch_request
    rv = self.dispatch_request()
  File "/Users/davidekim/tensorflow/lib/python3.9/site-packages/flask/app.py", line 1799, in dispatch_request
    return self.ensure_sync(self.view_functions[rule.endpoint])(**view_args)
  File "/Users/davidekim/Desktop/DataScience/Hackathon2/team561/flask-server.py", line 110, in insert_chore
    return response if 'error' in response else jsonify({'message': 'Chore added successfully'}), 201 if 'error' not in response else 500
TypeError: argument of type 'NoneType' is not iterable
werkzeug - INFO - 127.0.0.1 - - [18/Nov/2023 22:05:55] "[35m[1mPOST /api/insert-chore HTTP/1.1[0m" 500 -
root - INFO - Inserting chore: {'name': 'New Chore', 'compensation': 0}
flask-server - ERROR - Exception on /api/insert-chore [POST]
Traceback (most recent call last):
  File "/Users/davidekim/tensorflow/lib/python3.9/site-packages/flask/app.py", line 2529, in wsgi_app
    response = self.full_dispatch_request()
  File "/Users/davidekim/tensorflow/lib/python3.9/site-packages/flask/app.py", line 1825, in full_dispatch_request
    rv = self.handle_user_exception(e)
  File "/Users/davidekim/tensorflow/lib/python3.9/site-packages/flask_cors/extension.py", line 176, in wrapped_function
    return cors_after_request(app.make_response(f(*args, **kwargs)))
  File "/Users/davidekim/tensorflow/lib/python3.9/site-packages/flask/app.py", line 1823, in full_dispatch_request
    rv = self.dispatch_request()
  File "/Users/davidekim/tensorflow/lib/python3.9/site-packages/flask/app.py", line 1799, in dispatch_request
    return self.ensure_sync(self.view_functions[rule.endpoint])(**view_args)
  File "/Users/davidekim/Desktop/DataScience/Hackathon2/team561/flask-server.py", line 110, in insert_chore
    return response if 'error' in response else jsonify({'message': 'Chore added successfully'}), 201 if 'error' not in response else 500
TypeError: argument of type 'NoneType' is not iterable
werkzeug - INFO - 127.0.0.1 - - [18/Nov/2023 22:06:01] "[35m[1mPOST /api/insert-chore HTTP/1.1[0m" 500 -
root - INFO - Inserting chore: {'name': 'New Chore', 'compensation': 0}
flask-server - ERROR - Exception on /api/insert-chore [POST]
Traceback (most recent call last):
  File "/Users/davidekim/tensorflow/lib/python3.9/site-packages/flask/app.py", line 2529, in wsgi_app
    response = self.full_dispatch_request()
  File "/Users/davidekim/tensorflow/lib/python3.9/site-packages/flask/app.py", line 1825, in full_dispatch_request
    rv = self.handle_user_exception(e)
  File "/Users/davidekim/tensorflow/lib/python3.9/site-packages/flask_cors/extension.py", line 176, in wrapped_function
    return cors_after_request(app.make_response(f(*args, **kwargs)))
  File "/Users/davidekim/tensorflow/lib/python3.9/site-packages/flask/app.py", line 1823, in full_dispatch_request
    rv = self.dispatch_request()
  File "/Users/davidekim/tensorflow/lib/python3.9/site-packages/flask/app.py", line 1799, in dispatch_request
    return self.ensure_sync(self.view_functions[rule.endpoint])(**view_args)
  File "/Users/davidekim/Desktop/DataScience/Hackathon2/team561/flask-server.py", line 110, in insert_chore
    return response if 'error' in response else jsonify({'message': 'Chore added successfully'}), 201 if 'error' not in response else 500
TypeError: argument of type 'NoneType' is not iterable
werkzeug - INFO - 127.0.0.1 - - [18/Nov/2023 22:06:03] "[35m[1mPOST /api/insert-chore HTTP/1.1[0m" 500 -
root - INFO - Inserting chore: {'name': 'New Chore', 'compensation': 0}
root - INFO - Inserting chore: {'name': 'New Chore', 'compensation': 0}
flask-server - ERROR - Exception on /api/insert-chore [POST]
Traceback (most recent call last):
  File "/Users/davidekim/tensorflow/lib/python3.9/site-packages/flask/app.py", line 2529, in wsgi_app
    response = self.full_dispatch_request()
  File "/Users/davidekim/tensorflow/lib/python3.9/site-packages/flask/app.py", line 1825, in full_dispatch_request
    rv = self.handle_user_exception(e)
  File "/Users/davidekim/tensorflow/lib/python3.9/site-packages/flask_cors/extension.py", line 176, in wrapped_function
    return cors_after_request(app.make_response(f(*args, **kwargs)))
  File "/Users/davidekim/tensorflow/lib/python3.9/site-packages/flask/app.py", line 1823, in full_dispatch_request
    rv = self.dispatch_request()
  File "/Users/davidekim/tensorflow/lib/python3.9/site-packages/flask/app.py", line 1799, in dispatch_request
    return self.ensure_sync(self.view_functions[rule.endpoint])(**view_args)
  File "/Users/davidekim/Desktop/DataScience/Hackathon2/team561/flask-server.py", line 110, in insert_chore
    return response if 'error' in response else jsonify({'message': 'Chore added successfully'}), 201 if 'error' not in response else 500
TypeError: argument of type 'NoneType' is not iterable
werkzeug - INFO - 127.0.0.1 - - [18/Nov/2023 22:06:03] "[35m[1mPOST /api/insert-chore HTTP/1.1[0m" 500 -
flask-server - ERROR - Exception on /api/insert-chore [POST]
Traceback (most recent call last):
  File "/Users/davidekim/tensorflow/lib/python3.9/site-packages/flask/app.py", line 2529, in wsgi_app
    response = self.full_dispatch_request()
  File "/Users/davidekim/tensorflow/lib/python3.9/site-packages/flask/app.py", line 1825, in full_dispatch_request
    rv = self.handle_user_exception(e)
  File "/Users/davidekim/tensorflow/lib/python3.9/site-packages/flask_cors/extension.py", line 176, in wrapped_function
    return cors_after_request(app.make_response(f(*args, **kwargs)))
  File "/Users/davidekim/tensorflow/lib/python3.9/site-packages/flask/app.py", line 1823, in full_dispatch_request
    rv = self.dispatch_request()
  File "/Users/davidekim/tensorflow/lib/python3.9/site-packages/flask/app.py", line 1799, in dispatch_request
    return self.ensure_sync(self.view_functions[rule.endpoint])(**view_args)
  File "/Users/davidekim/Desktop/DataScience/Hackathon2/team561/flask-server.py", line 110, in insert_chore
    return response if 'error' in response else jsonify({'message': 'Chore added successfully'}), 201 if 'error' not in response else 500
TypeError: argument of type 'NoneType' is not iterable
werkzeug - INFO - 127.0.0.1 - - [18/Nov/2023 22:06:03] "[35m[1mPOST /api/insert-chore HTTP/1.1[0m" 500 -
root - INFO - Inserting chore: {'name': 'New Chore', 'compensation': 0}
root - INFO - Inserting chore: {'name': 'New Chore', 'compensation': 0}
root - INFO - Inserting chore: {'name': 'New Chore', 'compensation': 0}
flask-server - ERROR - Exception on /api/insert-chore [POST]
Traceback (most recent call last):
  File "/Users/davidekim/tensorflow/lib/python3.9/site-packages/flask/app.py", line 2529, in wsgi_app
    response = self.full_dispatch_request()
  File "/Users/davidekim/tensorflow/lib/python3.9/site-packages/flask/app.py", line 1825, in full_dispatch_request
    rv = self.handle_user_exception(e)
  File "/Users/davidekim/tensorflow/lib/python3.9/site-packages/flask_cors/extension.py", line 176, in wrapped_function
    return cors_after_request(app.make_response(f(*args, **kwargs)))
  File "/Users/davidekim/tensorflow/lib/python3.9/site-packages/flask/app.py", line 1823, in full_dispatch_request
    rv = self.dispatch_request()
  File "/Users/davidekim/tensorflow/lib/python3.9/site-packages/flask/app.py", line 1799, in dispatch_request
    return self.ensure_sync(self.view_functions[rule.endpoint])(**view_args)
  File "/Users/davidekim/Desktop/DataScience/Hackathon2/team561/flask-server.py", line 110, in insert_chore
    return response if 'error' in response else jsonify({'message': 'Chore added successfully'}), 201 if 'error' not in response else 500
TypeError: argument of type 'NoneType' is not iterable
werkzeug - INFO - 127.0.0.1 - - [18/Nov/2023 22:06:04] "[35m[1mPOST /api/insert-chore HTTP/1.1[0m" 500 -
flask-server - ERROR - Exception on /api/insert-chore [POST]
Traceback (most recent call last):
  File "/Users/davidekim/tensorflow/lib/python3.9/site-packages/flask/app.py", line 2529, in wsgi_app
    response = self.full_dispatch_request()
  File "/Users/davidekim/tensorflow/lib/python3.9/site-packages/flask/app.py", line 1825, in full_dispatch_request
    rv = self.handle_user_exception(e)
  File "/Users/davidekim/tensorflow/lib/python3.9/site-packages/flask_cors/extension.py", line 176, in wrapped_function
    return cors_after_request(app.make_response(f(*args, **kwargs)))
  File "/Users/davidekim/tensorflow/lib/python3.9/site-packages/flask/app.py", line 1823, in full_dispatch_request
    rv = self.dispatch_request()
  File "/Users/davidekim/tensorflow/lib/python3.9/site-packages/flask/app.py", line 1799, in dispatch_request
    return self.ensure_sync(self.view_functions[rule.endpoint])(**view_args)
  File "/Users/davidekim/Desktop/DataScience/Hackathon2/team561/flask-server.py", line 110, in insert_chore
    return response if 'error' in response else jsonify({'message': 'Chore added successfully'}), 201 if 'error' not in response else 500
TypeError: argument of type 'NoneType' is not iterable
werkzeug - INFO - 127.0.0.1 - - [18/Nov/2023 22:06:04] "[35m[1mPOST /api/insert-chore HTTP/1.1[0m" 500 -
flask-server - ERROR - Exception on /api/insert-chore [POST]
Traceback (most recent call last):
  File "/Users/davidekim/tensorflow/lib/python3.9/site-packages/flask/app.py", line 2529, in wsgi_app
    response = self.full_dispatch_request()
  File "/Users/davidekim/tensorflow/lib/python3.9/site-packages/flask/app.py", line 1825, in full_dispatch_request
    rv = self.handle_user_exception(e)
  File "/Users/davidekim/tensorflow/lib/python3.9/site-packages/flask_cors/extension.py", line 176, in wrapped_function
    return cors_after_request(app.make_response(f(*args, **kwargs)))
  File "/Users/davidekim/tensorflow/lib/python3.9/site-packages/flask/app.py", line 1823, in full_dispatch_request
    rv = self.dispatch_request()
  File "/Users/davidekim/tensorflow/lib/python3.9/site-packages/flask/app.py", line 1799, in dispatch_request
    return self.ensure_sync(self.view_functions[rule.endpoint])(**view_args)
  File "/Users/davidekim/Desktop/DataScience/Hackathon2/team561/flask-server.py", line 110, in insert_chore
    return response if 'error' in response else jsonify({'message': 'Chore added successfully'}), 201 if 'error' not in response else 500
TypeError: argument of type 'NoneType' is not iterable
werkzeug - INFO - 127.0.0.1 - - [18/Nov/2023 22:06:04] "[35m[1mPOST /api/insert-chore HTTP/1.1[0m" 500 -
root - INFO - Inserting chore: {'name': 'New Chore', 'compensation': 0}
root - INFO - Inserting chore: {'name': 'New Chore', 'compensation': 0}
flask-server - ERROR - Exception on /api/insert-chore [POST]
Traceback (most recent call last):
  File "/Users/davidekim/tensorflow/lib/python3.9/site-packages/flask/app.py", line 2529, in wsgi_app
    response = self.full_dispatch_request()
  File "/Users/davidekim/tensorflow/lib/python3.9/site-packages/flask/app.py", line 1825, in full_dispatch_request
    rv = self.handle_user_exception(e)
  File "/Users/davidekim/tensorflow/lib/python3.9/site-packages/flask_cors/extension.py", line 176, in wrapped_function
    return cors_after_request(app.make_response(f(*args, **kwargs)))
  File "/Users/davidekim/tensorflow/lib/python3.9/site-packages/flask/app.py", line 1823, in full_dispatch_request
    rv = self.dispatch_request()
  File "/Users/davidekim/tensorflow/lib/python3.9/site-packages/flask/app.py", line 1799, in dispatch_request
    return self.ensure_sync(self.view_functions[rule.endpoint])(**view_args)
  File "/Users/davidekim/Desktop/DataScience/Hackathon2/team561/flask-server.py", line 110, in insert_chore
    return response if 'error' in response else jsonify({'message': 'Chore added successfully'}), 201 if 'error' not in response else 500
TypeError: argument of type 'NoneType' is not iterable
flask-server - ERROR - Exception on /api/insert-chore [POST]
Traceback (most recent call last):
  File "/Users/davidekim/tensorflow/lib/python3.9/site-packages/flask/app.py", line 2529, in wsgi_app
    response = self.full_dispatch_request()
  File "/Users/davidekim/tensorflow/lib/python3.9/site-packages/flask/app.py", line 1825, in full_dispatch_request
    rv = self.handle_user_exception(e)
  File "/Users/davidekim/tensorflow/lib/python3.9/site-packages/flask_cors/extension.py", line 176, in wrapped_function
    return cors_after_request(app.make_response(f(*args, **kwargs)))
  File "/Users/davidekim/tensorflow/lib/python3.9/site-packages/flask/app.py", line 1823, in full_dispatch_request
    rv = self.dispatch_request()
  File "/Users/davidekim/tensorflow/lib/python3.9/site-packages/flask/app.py", line 1799, in dispatch_request
    return self.ensure_sync(self.view_functions[rule.endpoint])(**view_args)
  File "/Users/davidekim/Desktop/DataScience/Hackathon2/team561/flask-server.py", line 110, in insert_chore
    return response if 'error' in response else jsonify({'message': 'Chore added successfully'}), 201 if 'error' not in response else 500
TypeError: argument of type 'NoneType' is not iterable
werkzeug - INFO - 127.0.0.1 - - [18/Nov/2023 22:06:06] "[35m[1mPOST /api/insert-chore HTTP/1.1[0m" 500 -
werkzeug - INFO - 127.0.0.1 - - [18/Nov/2023 22:06:06] "[35m[1mPOST /api/insert-chore HTTP/1.1[0m" 500 -
root - INFO - Item retrieved successfully
flask-server - ERROR - Exception on /api/get-item [GET]
Traceback (most recent call last):
  File "/Users/davidekim/tensorflow/lib/python3.9/site-packages/flask/app.py", line 2529, in wsgi_app
    response = self.full_dispatch_request()
  File "/Users/davidekim/tensorflow/lib/python3.9/site-packages/flask/app.py", line 1825, in full_dispatch_request
    rv = self.handle_user_exception(e)
  File "/Users/davidekim/tensorflow/lib/python3.9/site-packages/flask_cors/extension.py", line 176, in wrapped_function
    return cors_after_request(app.make_response(f(*args, **kwargs)))
  File "/Users/davidekim/tensorflow/lib/python3.9/site-packages/flask/app.py", line 1823, in full_dispatch_request
    rv = self.dispatch_request()
  File "/Users/davidekim/tensorflow/lib/python3.9/site-packages/flask/app.py", line 1799, in dispatch_request
    return self.ensure_sync(self.view_functions[rule.endpoint])(**view_args)
  File "/Users/davidekim/Desktop/DataScience/Hackathon2/team561/flask-server.py", line 71, in get_item
    return jsonify(dict(result)) if result else jsonify({'error': 'No item found'}), 404 if not result else 200
ValueError: dictionary update sequence element #0 has length 7; 2 is required
werkzeug - INFO - 127.0.0.1 - - [18/Nov/2023 22:06:08] "[35m[1mGET /api/get-item HTTP/1.1[0m" 500 -
root - INFO - Chores retrieved successfully
flask-server - ERROR - Exception on /api/get-chores [GET]
Traceback (most recent call last):
  File "/Users/davidekim/tensorflow/lib/python3.9/site-packages/flask/app.py", line 2529, in wsgi_app
    response = self.full_dispatch_request()
  File "/Users/davidekim/tensorflow/lib/python3.9/site-packages/flask/app.py", line 1825, in full_dispatch_request
    rv = self.handle_user_exception(e)
  File "/Users/davidekim/tensorflow/lib/python3.9/site-packages/flask_cors/extension.py", line 176, in wrapped_function
    return cors_after_request(app.make_response(f(*args, **kwargs)))
  File "/Users/davidekim/tensorflow/lib/python3.9/site-packages/flask/app.py", line 1823, in full_dispatch_request
    rv = self.dispatch_request()
  File "/Users/davidekim/tensorflow/lib/python3.9/site-packages/flask/app.py", line 1799, in dispatch_request
    return self.ensure_sync(self.view_functions[rule.endpoint])(**view_args)
  File "/Users/davidekim/Desktop/DataScience/Hackathon2/team561/flask-server.py", line 120, in get_chores
    return jsonify([dict(row) for row in chores]), 200
  File "/Users/davidekim/Desktop/DataScience/Hackathon2/team561/flask-server.py", line 120, in <listcomp>
    return jsonify([dict(row) for row in chores]), 200
ValueError: dictionary update sequence element #0 has length 12; 2 is required
werkzeug - INFO - 127.0.0.1 - - [18/Nov/2023 22:06:08] "[35m[1mGET /api/get-chores HTTP/1.1[0m" 500 -
root - INFO - Total balance calculated successfully
werkzeug - INFO - 127.0.0.1 - - [18/Nov/2023 22:06:08] "GET /api/get-total-balance HTTP/1.1" 200 -
werkzeug - INFO - [31m[1mWARNING: This is a development server. Do not use it in a production deployment. Use a production WSGI server instead.[0m
 * Running on http://127.0.0.1:5000
werkzeug - INFO - [33mPress CTRL+C to quit[0m
root - INFO - Chores retrieved successfully
flask-server - ERROR - Exception on /api/get-chores [GET]
Traceback (most recent call last):
  File "/Users/davidekim/tensorflow/lib/python3.9/site-packages/flask/app.py", line 2529, in wsgi_app
    response = self.full_dispatch_request()
  File "/Users/davidekim/tensorflow/lib/python3.9/site-packages/flask/app.py", line 1825, in full_dispatch_request
    rv = self.handle_user_exception(e)
  File "/Users/davidekim/tensorflow/lib/python3.9/site-packages/flask_cors/extension.py", line 176, in wrapped_function
    return cors_after_request(app.make_response(f(*args, **kwargs)))
  File "/Users/davidekim/tensorflow/lib/python3.9/site-packages/flask/app.py", line 1823, in full_dispatch_request
    rv = self.dispatch_request()
  File "/Users/davidekim/tensorflow/lib/python3.9/site-packages/flask/app.py", line 1799, in dispatch_request
    return self.ensure_sync(self.view_functions[rule.endpoint])(**view_args)
  File "/Users/davidekim/Desktop/DataScience/Hackathon2/team561/flask-server.py", line 120, in get_chores
    return jsonify([dict(row) for row in chores]), 200
  File "/Users/davidekim/Desktop/DataScience/Hackathon2/team561/flask-server.py", line 120, in <listcomp>
    return jsonify([dict(row) for row in chores]), 200
ValueError: dictionary update sequence element #0 has length 12; 2 is required
werkzeug - INFO - 127.0.0.1 - - [18/Nov/2023 22:22:51] "[35m[1mGET /api/get-chores HTTP/1.1[0m" 500 -
root - INFO - Allowance retrieved successfully
flask-server - ERROR - Exception on /api/get-allowance [GET]
Traceback (most recent call last):
  File "/Users/davidekim/tensorflow/lib/python3.9/site-packages/flask/app.py", line 2529, in wsgi_app
    response = self.full_dispatch_request()
  File "/Users/davidekim/tensorflow/lib/python3.9/site-packages/flask/app.py", line 1825, in full_dispatch_request
    rv = self.handle_user_exception(e)
  File "/Users/davidekim/tensorflow/lib/python3.9/site-packages/flask_cors/extension.py", line 176, in wrapped_function
    return cors_after_request(app.make_response(f(*args, **kwargs)))
  File "/Users/davidekim/tensorflow/lib/python3.9/site-packages/flask/app.py", line 1823, in full_dispatch_request
    rv = self.dispatch_request()
  File "/Users/davidekim/tensorflow/lib/python3.9/site-packages/flask/app.py", line 1799, in dispatch_request
    return self.ensure_sync(self.view_functions[rule.endpoint])(**view_args)
  File "/Users/davidekim/Desktop/DataScience/Hackathon2/team561/flask-server.py", line 97, in get_allowance
    return jsonify({'allowance': result['amount'] if result else 0}), 200
  File "lib/sqlalchemy/cyextension/resultproxy.pyx", line 48, in sqlalchemy.cyextension.resultproxy.BaseRow.__getitem__
TypeError: tuple indices must be integers or slices, not str
werkzeug - INFO - 127.0.0.1 - - [18/Nov/2023 22:22:51] "[35m[1mGET /api/get-allowance HTTP/1.1[0m" 500 -
root - INFO - Allowance retrieved successfully
flask-server - ERROR - Exception on /api/get-allowance [GET]
Traceback (most recent call last):
  File "/Users/davidekim/tensorflow/lib/python3.9/site-packages/flask/app.py", line 2529, in wsgi_app
    response = self.full_dispatch_request()
  File "/Users/davidekim/tensorflow/lib/python3.9/site-packages/flask/app.py", line 1825, in full_dispatch_request
    rv = self.handle_user_exception(e)
  File "/Users/davidekim/tensorflow/lib/python3.9/site-packages/flask_cors/extension.py", line 176, in wrapped_function
    return cors_after_request(app.make_response(f(*args, **kwargs)))
  File "/Users/davidekim/tensorflow/lib/python3.9/site-packages/flask/app.py", line 1823, in full_dispatch_request
    rv = self.dispatch_request()
  File "/Users/davidekim/tensorflow/lib/python3.9/site-packages/flask/app.py", line 1799, in dispatch_request
    return self.ensure_sync(self.view_functions[rule.endpoint])(**view_args)
  File "/Users/davidekim/Desktop/DataScience/Hackathon2/team561/flask-server.py", line 97, in get_allowance
    return jsonify({'allowance': result['amount'] if result else 0}), 200
  File "lib/sqlalchemy/cyextension/resultproxy.pyx", line 48, in sqlalchemy.cyextension.resultproxy.BaseRow.__getitem__
TypeError: tuple indices must be integers or slices, not str
root - INFO - Chores retrieved successfully
werkzeug - INFO - 127.0.0.1 - - [18/Nov/2023 22:30:49] "[35m[1mGET /api/get-allowance HTTP/1.1[0m" 500 -
flask-server - ERROR - Exception on /api/get-chores [GET]
Traceback (most recent call last):
  File "/Users/davidekim/tensorflow/lib/python3.9/site-packages/flask/app.py", line 2529, in wsgi_app
    response = self.full_dispatch_request()
  File "/Users/davidekim/tensorflow/lib/python3.9/site-packages/flask/app.py", line 1825, in full_dispatch_request
    rv = self.handle_user_exception(e)
  File "/Users/davidekim/tensorflow/lib/python3.9/site-packages/flask_cors/extension.py", line 176, in wrapped_function
    return cors_after_request(app.make_response(f(*args, **kwargs)))
  File "/Users/davidekim/tensorflow/lib/python3.9/site-packages/flask/app.py", line 1823, in full_dispatch_request
    rv = self.dispatch_request()
  File "/Users/davidekim/tensorflow/lib/python3.9/site-packages/flask/app.py", line 1799, in dispatch_request
    return self.ensure_sync(self.view_functions[rule.endpoint])(**view_args)
  File "/Users/davidekim/Desktop/DataScience/Hackathon2/team561/flask-server.py", line 120, in get_chores
    return jsonify([dict(row) for row in chores]), 200
  File "/Users/davidekim/Desktop/DataScience/Hackathon2/team561/flask-server.py", line 120, in <listcomp>
    return jsonify([dict(row) for row in chores]), 200
ValueError: dictionary update sequence element #0 has length 12; 2 is required
werkzeug - INFO - 127.0.0.1 - - [18/Nov/2023 22:30:49] "[35m[1mGET /api/get-chores HTTP/1.1[0m" 500 -
root - INFO - Allowance retrieved successfully
flask-server - ERROR - Exception on /api/get-allowance [GET]
Traceback (most recent call last):
  File "/Users/davidekim/tensorflow/lib/python3.9/site-packages/flask/app.py", line 2529, in wsgi_app
    response = self.full_dispatch_request()
  File "/Users/davidekim/tensorflow/lib/python3.9/site-packages/flask/app.py", line 1825, in full_dispatch_request
    rv = self.handle_user_exception(e)
  File "/Users/davidekim/tensorflow/lib/python3.9/site-packages/flask_cors/extension.py", line 176, in wrapped_function
    return cors_after_request(app.make_response(f(*args, **kwargs)))
  File "/Users/davidekim/tensorflow/lib/python3.9/site-packages/flask/app.py", line 1823, in full_dispatch_request
    rv = self.dispatch_request()
  File "/Users/davidekim/tensorflow/lib/python3.9/site-packages/flask/app.py", line 1799, in dispatch_request
    return self.ensure_sync(self.view_functions[rule.endpoint])(**view_args)
  File "/Users/davidekim/Desktop/DataScience/Hackathon2/team561/flask-server.py", line 97, in get_allowance
    return jsonify({'allowance': result['amount'] if result else 0}), 200
  File "lib/sqlalchemy/cyextension/resultproxy.pyx", line 48, in sqlalchemy.cyextension.resultproxy.BaseRow.__getitem__
TypeError: tuple indices must be integers or slices, not str
werkzeug - INFO - 127.0.0.1 - - [18/Nov/2023 22:30:51] "[35m[1mGET /api/get-allowance HTTP/1.1[0m" 500 -
root - INFO - Chores retrieved successfully
flask-server - ERROR - Exception on /api/get-chores [GET]
Traceback (most recent call last):
  File "/Users/davidekim/tensorflow/lib/python3.9/site-packages/flask/app.py", line 2529, in wsgi_app
    response = self.full_dispatch_request()
  File "/Users/davidekim/tensorflow/lib/python3.9/site-packages/flask/app.py", line 1825, in full_dispatch_request
    rv = self.handle_user_exception(e)
  File "/Users/davidekim/tensorflow/lib/python3.9/site-packages/flask_cors/extension.py", line 176, in wrapped_function
    return cors_after_request(app.make_response(f(*args, **kwargs)))
  File "/Users/davidekim/tensorflow/lib/python3.9/site-packages/flask/app.py", line 1823, in full_dispatch_request
    rv = self.dispatch_request()
  File "/Users/davidekim/tensorflow/lib/python3.9/site-packages/flask/app.py", line 1799, in dispatch_request
    return self.ensure_sync(self.view_functions[rule.endpoint])(**view_args)
  File "/Users/davidekim/Desktop/DataScience/Hackathon2/team561/flask-server.py", line 120, in get_chores
    return jsonify([dict(row) for row in chores]), 200
  File "/Users/davidekim/Desktop/DataScience/Hackathon2/team561/flask-server.py", line 120, in <listcomp>
    return jsonify([dict(row) for row in chores]), 200
ValueError: dictionary update sequence element #0 has length 12; 2 is required
werkzeug - INFO - 127.0.0.1 - - [18/Nov/2023 22:30:51] "[35m[1mGET /api/get-chores HTTP/1.1[0m" 500 -
root - INFO - Allowance retrieved successfully
root - INFO - Chores retrieved successfully
flask-server - ERROR - Exception on /api/get-allowance [GET]
Traceback (most recent call last):
  File "/Users/davidekim/tensorflow/lib/python3.9/site-packages/flask/app.py", line 2529, in wsgi_app
    response = self.full_dispatch_request()
  File "/Users/davidekim/tensorflow/lib/python3.9/site-packages/flask/app.py", line 1825, in full_dispatch_request
    rv = self.handle_user_exception(e)
  File "/Users/davidekim/tensorflow/lib/python3.9/site-packages/flask_cors/extension.py", line 176, in wrapped_function
    return cors_after_request(app.make_response(f(*args, **kwargs)))
  File "/Users/davidekim/tensorflow/lib/python3.9/site-packages/flask/app.py", line 1823, in full_dispatch_request
    rv = self.dispatch_request()
  File "/Users/davidekim/tensorflow/lib/python3.9/site-packages/flask/app.py", line 1799, in dispatch_request
    return self.ensure_sync(self.view_functions[rule.endpoint])(**view_args)
  File "/Users/davidekim/Desktop/DataScience/Hackathon2/team561/flask-server.py", line 97, in get_allowance
    return jsonify({'allowance': result['amount'] if result else 0}), 200
  File "lib/sqlalchemy/cyextension/resultproxy.pyx", line 48, in sqlalchemy.cyextension.resultproxy.BaseRow.__getitem__
TypeError: tuple indices must be integers or slices, not str
flask-server - ERROR - Exception on /api/get-chores [GET]
Traceback (most recent call last):
  File "/Users/davidekim/tensorflow/lib/python3.9/site-packages/flask/app.py", line 2529, in wsgi_app
    response = self.full_dispatch_request()
  File "/Users/davidekim/tensorflow/lib/python3.9/site-packages/flask/app.py", line 1825, in full_dispatch_request
    rv = self.handle_user_exception(e)
  File "/Users/davidekim/tensorflow/lib/python3.9/site-packages/flask_cors/extension.py", line 176, in wrapped_function
    return cors_after_request(app.make_response(f(*args, **kwargs)))
  File "/Users/davidekim/tensorflow/lib/python3.9/site-packages/flask/app.py", line 1823, in full_dispatch_request
    rv = self.dispatch_request()
  File "/Users/davidekim/tensorflow/lib/python3.9/site-packages/flask/app.py", line 1799, in dispatch_request
    return self.ensure_sync(self.view_functions[rule.endpoint])(**view_args)
  File "/Users/davidekim/Desktop/DataScience/Hackathon2/team561/flask-server.py", line 120, in get_chores
    return jsonify([dict(row) for row in chores]), 200
  File "/Users/davidekim/Desktop/DataScience/Hackathon2/team561/flask-server.py", line 120, in <listcomp>
    return jsonify([dict(row) for row in chores]), 200
ValueError: dictionary update sequence element #0 has length 12; 2 is required
werkzeug - INFO - 127.0.0.1 - - [18/Nov/2023 22:30:55] "[35m[1mGET /api/get-allowance HTTP/1.1[0m" 500 -
werkzeug - INFO - 127.0.0.1 - - [18/Nov/2023 22:30:55] "[35m[1mGET /api/get-chores HTTP/1.1[0m" 500 -
root - INFO - Allowance retrieved successfully
root - INFO - Chores retrieved successfully
flask-server - ERROR - Exception on /api/get-allowance [GET]
Traceback (most recent call last):
  File "/Users/davidekim/tensorflow/lib/python3.9/site-packages/flask/app.py", line 2529, in wsgi_app
    response = self.full_dispatch_request()
  File "/Users/davidekim/tensorflow/lib/python3.9/site-packages/flask/app.py", line 1825, in full_dispatch_request
    rv = self.handle_user_exception(e)
  File "/Users/davidekim/tensorflow/lib/python3.9/site-packages/flask_cors/extension.py", line 176, in wrapped_function
    return cors_after_request(app.make_response(f(*args, **kwargs)))
  File "/Users/davidekim/tensorflow/lib/python3.9/site-packages/flask/app.py", line 1823, in full_dispatch_request
    rv = self.dispatch_request()
  File "/Users/davidekim/tensorflow/lib/python3.9/site-packages/flask/app.py", line 1799, in dispatch_request
    return self.ensure_sync(self.view_functions[rule.endpoint])(**view_args)
  File "/Users/davidekim/Desktop/DataScience/Hackathon2/team561/flask-server.py", line 97, in get_allowance
    return jsonify({'allowance': result['amount'] if result else 0}), 200
  File "lib/sqlalchemy/cyextension/resultproxy.pyx", line 48, in sqlalchemy.cyextension.resultproxy.BaseRow.__getitem__
TypeError: tuple indices must be integers or slices, not str
flask-server - ERROR - Exception on /api/get-chores [GET]
Traceback (most recent call last):
  File "/Users/davidekim/tensorflow/lib/python3.9/site-packages/flask/app.py", line 2529, in wsgi_app
    response = self.full_dispatch_request()
  File "/Users/davidekim/tensorflow/lib/python3.9/site-packages/flask/app.py", line 1825, in full_dispatch_request
    rv = self.handle_user_exception(e)
  File "/Users/davidekim/tensorflow/lib/python3.9/site-packages/flask_cors/extension.py", line 176, in wrapped_function
    return cors_after_request(app.make_response(f(*args, **kwargs)))
  File "/Users/davidekim/tensorflow/lib/python3.9/site-packages/flask/app.py", line 1823, in full_dispatch_request
    rv = self.dispatch_request()
  File "/Users/davidekim/tensorflow/lib/python3.9/site-packages/flask/app.py", line 1799, in dispatch_request
    return self.ensure_sync(self.view_functions[rule.endpoint])(**view_args)
  File "/Users/davidekim/Desktop/DataScience/Hackathon2/team561/flask-server.py", line 120, in get_chores
    return jsonify([dict(row) for row in chores]), 200
  File "/Users/davidekim/Desktop/DataScience/Hackathon2/team561/flask-server.py", line 120, in <listcomp>
    return jsonify([dict(row) for row in chores]), 200
ValueError: dictionary update sequence element #0 has length 12; 2 is required
werkzeug - INFO - 127.0.0.1 - - [18/Nov/2023 22:32:05] "[35m[1mGET /api/get-allowance HTTP/1.1[0m" 500 -
werkzeug - INFO - 127.0.0.1 - - [18/Nov/2023 22:32:05] "[35m[1mGET /api/get-chores HTTP/1.1[0m" 500 -
werkzeug - INFO - [31m[1mWARNING: This is a development server. Do not use it in a production deployment. Use a production WSGI server instead.[0m
 * Running on http://127.0.0.1:5000
werkzeug - INFO - [33mPress CTRL+C to quit[0m
root - INFO - Chores retrieved successfully
flask-server - ERROR - Exception on /api/get-chores [GET]
Traceback (most recent call last):
  File "/Users/davidekim/tensorflow/lib/python3.9/site-packages/flask/app.py", line 2529, in wsgi_app
    response = self.full_dispatch_request()
  File "/Users/davidekim/tensorflow/lib/python3.9/site-packages/flask/app.py", line 1825, in full_dispatch_request
    rv = self.handle_user_exception(e)
  File "/Users/davidekim/tensorflow/lib/python3.9/site-packages/flask_cors/extension.py", line 176, in wrapped_function
    return cors_after_request(app.make_response(f(*args, **kwargs)))
  File "/Users/davidekim/tensorflow/lib/python3.9/site-packages/flask/app.py", line 1823, in full_dispatch_request
    rv = self.dispatch_request()
  File "/Users/davidekim/tensorflow/lib/python3.9/site-packages/flask/app.py", line 1799, in dispatch_request
    return self.ensure_sync(self.view_functions[rule.endpoint])(**view_args)
  File "/Users/davidekim/Desktop/DataScience/Hackathon2/team561/flask-server.py", line 120, in get_chores
    return jsonify([dict(row) for row in chores]), 200
  File "/Users/davidekim/Desktop/DataScience/Hackathon2/team561/flask-server.py", line 120, in <listcomp>
    return jsonify([dict(row) for row in chores]), 200
ValueError: dictionary update sequence element #0 has length 12; 2 is required
werkzeug - INFO - 127.0.0.1 - - [18/Nov/2023 22:32:19] "[35m[1mGET /api/get-chores HTTP/1.1[0m" 500 -
root - INFO - Allowance retrieved successfully
flask-server - ERROR - Exception on /api/get-allowance [GET]
Traceback (most recent call last):
  File "/Users/davidekim/tensorflow/lib/python3.9/site-packages/flask/app.py", line 2529, in wsgi_app
    response = self.full_dispatch_request()
  File "/Users/davidekim/tensorflow/lib/python3.9/site-packages/flask/app.py", line 1825, in full_dispatch_request
    rv = self.handle_user_exception(e)
  File "/Users/davidekim/tensorflow/lib/python3.9/site-packages/flask_cors/extension.py", line 176, in wrapped_function
    return cors_after_request(app.make_response(f(*args, **kwargs)))
  File "/Users/davidekim/tensorflow/lib/python3.9/site-packages/flask/app.py", line 1823, in full_dispatch_request
    rv = self.dispatch_request()
  File "/Users/davidekim/tensorflow/lib/python3.9/site-packages/flask/app.py", line 1799, in dispatch_request
    return self.ensure_sync(self.view_functions[rule.endpoint])(**view_args)
  File "/Users/davidekim/Desktop/DataScience/Hackathon2/team561/flask-server.py", line 97, in get_allowance
    return jsonify({'allowance': result['amount'] if result else 0}), 200
  File "lib/sqlalchemy/cyextension/resultproxy.pyx", line 48, in sqlalchemy.cyextension.resultproxy.BaseRow.__getitem__
TypeError: tuple indices must be integers or slices, not str
werkzeug - INFO - 127.0.0.1 - - [18/Nov/2023 22:32:19] "[35m[1mGET /api/get-allowance HTTP/1.1[0m" 500 -
root - INFO - Chores retrieved successfully
flask-server - ERROR - Exception on /api/get-chores [GET]
Traceback (most recent call last):
  File "/Users/davidekim/tensorflow/lib/python3.9/site-packages/flask/app.py", line 2529, in wsgi_app
    response = self.full_dispatch_request()
  File "/Users/davidekim/tensorflow/lib/python3.9/site-packages/flask/app.py", line 1825, in full_dispatch_request
    rv = self.handle_user_exception(e)
  File "/Users/davidekim/tensorflow/lib/python3.9/site-packages/flask_cors/extension.py", line 176, in wrapped_function
    return cors_after_request(app.make_response(f(*args, **kwargs)))
  File "/Users/davidekim/tensorflow/lib/python3.9/site-packages/flask/app.py", line 1823, in full_dispatch_request
    rv = self.dispatch_request()
  File "/Users/davidekim/tensorflow/lib/python3.9/site-packages/flask/app.py", line 1799, in dispatch_request
    return self.ensure_sync(self.view_functions[rule.endpoint])(**view_args)
  File "/Users/davidekim/Desktop/DataScience/Hackathon2/team561/flask-server.py", line 120, in get_chores
    return jsonify([dict(row) for row in chores]), 200
  File "/Users/davidekim/Desktop/DataScience/Hackathon2/team561/flask-server.py", line 120, in <listcomp>
    return jsonify([dict(row) for row in chores]), 200
ValueError: dictionary update sequence element #0 has length 12; 2 is required
werkzeug - INFO - 127.0.0.1 - - [18/Nov/2023 22:33:52] "[35m[1mGET /api/get-chores HTTP/1.1[0m" 500 -
werkzeug - INFO - [31m[1mWARNING: This is a development server. Do not use it in a production deployment. Use a production WSGI server instead.[0m
 * Running on http://127.0.0.1:5000
werkzeug - INFO - [33mPress CTRL+C to quit[0m
werkzeug - INFO - [31m[1mWARNING: This is a development server. Do not use it in a production deployment. Use a production WSGI server instead.[0m
 * Running on http://127.0.0.1:5000
werkzeug - INFO - [33mPress CTRL+C to quit[0m
werkzeug - INFO - [31m[1mWARNING: This is a development server. Do not use it in a production deployment. Use a production WSGI server instead.[0m
 * Running on http://127.0.0.1:5000
werkzeug - INFO - [33mPress CTRL+C to quit[0m
werkzeug - INFO - [31m[1mWARNING: This is a development server. Do not use it in a production deployment. Use a production WSGI server instead.[0m
 * Running on http://127.0.0.1:5000
werkzeug - INFO - [33mPress CTRL+C to quit[0m
werkzeug - INFO - [31m[1mWARNING: This is a development server. Do not use it in a production deployment. Use a production WSGI server instead.[0m
 * Running on http://127.0.0.1:5000
werkzeug - INFO - [33mPress CTRL+C to quit[0m
werkzeug - INFO - [31m[1mWARNING: This is a development server. Do not use it in a production deployment. Use a production WSGI server instead.[0m
 * Running on http://127.0.0.1:5000
werkzeug - INFO - [33mPress CTRL+C to quit[0m
werkzeug - INFO - [31m[1mWARNING: This is a development server. Do not use it in a production deployment. Use a production WSGI server instead.[0m
 * Running on http://127.0.0.1:5000
werkzeug - INFO - [33mPress CTRL+C to quit[0m
werkzeug - INFO - 127.0.0.1 - - [18/Nov/2023 23:12:13] "[33mGET / HTTP/1.1[0m" 404 -
werkzeug - INFO - 127.0.0.1 - - [18/Nov/2023 23:12:13] "[33mGET /favicon.ico HTTP/1.1[0m" 404 -
flask-server - ERROR - Exception on /api/get-total-balance [GET]
Traceback (most recent call last):
  File "/Users/davidekim/tensorflow/lib/python3.9/site-packages/flask/app.py", line 2529, in wsgi_app
    response = self.full_dispatch_request()
  File "/Users/davidekim/tensorflow/lib/python3.9/site-packages/flask/app.py", line 1825, in full_dispatch_request
    rv = self.handle_user_exception(e)
  File "/Users/davidekim/tensorflow/lib/python3.9/site-packages/flask_cors/extension.py", line 176, in wrapped_function
    return cors_after_request(app.make_response(f(*args, **kwargs)))
  File "/Users/davidekim/tensorflow/lib/python3.9/site-packages/flask/app.py", line 1823, in full_dispatch_request
    rv = self.dispatch_request()
  File "/Users/davidekim/tensorflow/lib/python3.9/site-packages/flask/app.py", line 1799, in dispatch_request
    return self.ensure_sync(self.view_functions[rule.endpoint])(**view_args)
  File "/Users/davidekim/Desktop/DataScience/Hackathon2/team561/flask-server.py", line 127, in get_total_balance
    total_compensation_result, compensation_error = execute_query(
ValueError: not enough values to unpack (expected 2, got 1)
werkzeug - INFO - 127.0.0.1 - - [18/Nov/2023 23:20:00] "[35m[1mGET /api/get-total-balance HTTP/1.1[0m" 500 -
flask-server - ERROR - Exception on /api/get-chores [GET]
Traceback (most recent call last):
  File "/Users/davidekim/tensorflow/lib/python3.9/site-packages/flask/app.py", line 2529, in wsgi_app
    response = self.full_dispatch_request()
  File "/Users/davidekim/tensorflow/lib/python3.9/site-packages/flask/app.py", line 1825, in full_dispatch_request
    rv = self.handle_user_exception(e)
  File "/Users/davidekim/tensorflow/lib/python3.9/site-packages/flask_cors/extension.py", line 176, in wrapped_function
    return cors_after_request(app.make_response(f(*args, **kwargs)))
  File "/Users/davidekim/tensorflow/lib/python3.9/site-packages/flask/app.py", line 1823, in full_dispatch_request
    rv = self.dispatch_request()
  File "/Users/davidekim/tensorflow/lib/python3.9/site-packages/flask/app.py", line 1799, in dispatch_request
    return self.ensure_sync(self.view_functions[rule.endpoint])(**view_args)
  File "/Users/davidekim/Desktop/DataScience/Hackathon2/team561/flask-server.py", line 116, in get_chores
    result, error = execute_query(
ValueError: too many values to unpack (expected 2)
werkzeug - INFO - 127.0.0.1 - - [18/Nov/2023 23:20:00] "[35m[1mGET /api/get-chores HTTP/1.1[0m" 500 -
werkzeug - INFO - [31m[1mWARNING: This is a development server. Do not use it in a production deployment. Use a production WSGI server instead.[0m
 * Running on http://localhost:5000
werkzeug - INFO - [33mPress CTRL+C to quit[0m
werkzeug - INFO - [31m[1mWARNING: This is a development server. Do not use it in a production deployment. Use a production WSGI server instead.[0m
 * Running on http://localhost:5000
werkzeug - INFO - [33mPress CTRL+C to quit[0m
werkzeug - INFO - [31m[1mWARNING: This is a development server. Do not use it in a production deployment. Use a production WSGI server instead.[0m
 * Running on http://localhost:5000
werkzeug - INFO - [33mPress CTRL+C to quit[0m
